Workbook

Sheet データ
A1: . | B1: 属性値 | C1: 地番（推定） | D1: （㎡） | E1: 収穫日１ | F1: 収穫日２ | G1: 小ﾛｰﾙ200kg | H1: 中ﾛｰﾙ250kg | I1: 微ﾛｰﾙ300kg | J1: 納入先 | K1: 出庫日 | L1: 区分 | M1: 備考（出庫日②） | N1: 収穫者 | P1: 栽培品種 | Q1: 栽培方法 | R1: 収量ｋｇ | S1: 単収ｋｇ
A2: Polygon((132.82524079084435.4121572540504,132.82520055770935.4122534385822,132.8251147270235.4124392492844,132.82504230737735.4126316175601,132.82420009374635.4123780411004,132.82428056001735.4121944162694,132.82435834407835.4120348372075,132.82442003488535.4119167922186,132.82524079084435.4121572540504)) | B2: （株）錦織農園 | C2: 島根県出雲市斐川町原鹿1671 | D2: 4503 | E2: 10/27 | F2: 10/27 | I2: 44 | P2: たちすずか | Q2: 直播（乾田） | R2: =SUM(200*$G2+250*$H2+300*$I2) -> 13200 | S2: =R2/D2*1000 -> 2931.3791
A3: Polygon((132.82616347074535.4130841183979,132.82511204481135.4127846374514,132.8252515196835.4124611093388,132.82535612583235.4122031603185,132.82641291618335.4124960854136,132.82629489898735.4127715214721,132.82616347074535.4130841183979)) | B3: （株）錦織農園 | C3: 島根県出雲市斐川町原鹿1690 | D3: 6893 | E3: 10/27 | F3: 10/27 | I3: 55 | P3: たちすずか | Q3: 直播（乾田） | R3: =SUM(200*$G3+250*$H3+300*$I3) -> 16500 | S3: =R3/D3*1000 -> 2393.7328
A4: Polygon((132.82749116420735.4128043114164,132.82737314701135.4130819324097,132.8273758292235.4130841183979,132.82726049423235.4133748543105,132.82725781202335.4133748543105,132.82703518867535.4139519510595,132.82651484012635.4137377262335,132.82604813575735.4134928971636,132.82621979713435.413073188456,132.82635122537635.4127715214721,132.82635390758535.4127715214721,132.82646656036435.41250482943,132.82749116420735.4128043114164)) | B4: （株）錦織農園 | C4: 島根県出雲市斐川町原鹿1709 | D4: 12446 | E4: 10/28 | F4: 10/28 | I4: 117 | P4: たちすずか | Q4: 直播（乾田） | R4: =SUM(200*$G4+250*$H4+300*$I4) -> 35100 | S4: =R4/D4*1000 -> 2820.1832
A5: Polygon((132.82434225082435.4146295972692,132.82489478588135.4148481916051,132.82510399818435.4143672832834,132.82551705837235.4145290436756,132.82579064469235.4139825545596,132.82475531101235.4136284276335,132.82434225082435.4146295972692)) | B5: （株）錦織農園 | C5: 島根県出雲市斐川町原鹿2032 | D5: 9564 | E5: 10/28 | F5: 10/28 | I5: 96 | P5: たちすずか | Q5: 直播（乾田） | R5: =SUM(200*$G5+250*$H5+300*$I5) -> 28800 | S5: =R5/D5*1000 -> 3011.2923
A6: Polygon((132.82602936029435.413735540263,132.8258496522935.4140678071057,132.82677769660935.4144022585309,132.82694131135935.4141071544042,132.82602936029435.413735540263)) | B6: （株）錦織農園 | C6: 島根県出雲市斐川町原鹿2048 | D6: 3463 | E6: 10/29 | F6: 10/29 | I6: 30 | P6: たちすずか | Q6: 直播（乾田） | R6: =SUM(200*$G6+250*$H6+300*$I6) -> 9000 | S6: =R6/D6*1000 -> 2598.9027
A7: Polygon((132.82677233219135.4144197461489,132.82665967941335.4146252253765,132.82572627067635.4142907748767,132.82583892345435.4140852947963,132.82677233219135.4144197461489)) | B7: （株）錦織農園 | C7: 島根県出雲市斐川町原鹿2049 | D7: 2438 | E7: 10/29 | F7: 10/29 | I7: 25 | P7: たちすずか | Q7: 直播（乾田） | R7: =SUM(200*$G7+250*$H7+300*$I7) -> 7500 | S7: =R7/D7*1000 -> 3076.292
A8: Polygon((132.82644242048335.4150055791597,132.8266409039535.4146361551079,132.8257155418435.4143038906087,132.82551705837235.414677688074,132.82644242048335.4150055791597)) | B8: （株）錦織農園 | C8: 島根県出雲市斐川町原鹿2050 | D8: 4177 | E8: 10/29 | F8: 10/29 | I8: 40 | P8: たちすずか | Q8: 直播（乾田） | R8: =SUM(200*$G8+250*$H8+300*$I8) -> 12000 | S8: =R8/D8*1000 -> 2872.8753
A9: Polygon((132.82494306564335.4168854622971,132.82507717609435.416623155655,132.82456755638135.4164439122919,132.82468289136935.4162187645756,132.82444953918535.4161531874525,132.8241893649135.416623155655,132.82494306564335.4168854622971)) | B9: （株）錦織農園 | C9: 島根県出雲市斐川町原鹿2171 | D9: 2888 | E9: 10/28 | F9: 10/28 | G9: 26 | P9: たちすずか | Q9: 直播（乾田） | R9: =SUM(200*$G9+250*$H9+300*$I9) -> 5200 | S9: =R9/D9*1000 -> 1800.554
A10: Polygon((132.82496988773335.4168898340672,132.82543659210235.4170515893953,132.82571017742235.4165575788611,132.82523274421735.4164001943379,132.82496988773335.4168898340672)) | B10: （株）錦織農園 | C10: 島根県出雲市斐川町原鹿2175 | D10: 2980 | E10: 10/21 | F10: 10/21 | G10: 33 | P10: たちすずか | Q10: 直播（乾田） | R10: =SUM(200*$G10+250*$H10+300*$I10) -> 6600 | S10: =R10/D10*1000 -> 2214.7651
A11: Polygon((132.82508254051235.4176986074604,132.82540440559435.4171040505131,132.82502889633235.4169728976546,132.82471239566835.4175587121028,132.82508254051235.4176986074604)) | B11: （株）錦織農園 | C11: 島根県出雲市斐川町原鹿2178 | D11: 3017 | E11: 10/21 | F11: 10/21 | G11: 36 | P11: たちすずか | Q11: 直播（乾田） | R11: =SUM(200*$G11+250*$H11+300*$I11) -> 7200 | S11: =R11/D11*1000 -> 2386.4766
A12: Polygon((132.8420233726535.4140131580481,132.84235328435935.4141749191511,132.8425410389935.4139934843783,132.84260809421535.4139978563053,132.8428146243135.4137246104093,132.8424042463335.4135388026708,132.8420233726535.4140131580481)) | B12: （株）錦織農園 | C12: 島根県出雲市斐川町黒目593-1-1（1) | D12: 2575 | E12: 10/27 | F12: 10/27 | G12: 26 | P12: たちすずか | Q12: 直播（乾田） | R12: =SUM(200*$G12+250*$H12+300*$I12) -> 5200 | S12: =R12/D12*1000 -> 2019.4175
A13: Polygon((132.84366488456735.41394757913,132.84418523311635.4142011506508,132.84423351287835.4141311999661,132.84442931413735.4142011506508,132.84472703933735.4136459154195,132.84397870302235.4133792262711,132.84366488456735.41394757913)) | B13: （株）錦織農園 | C13: 島根県出雲市斐川町黒目650 | D13: 5309 | E13: 10/25 | F13: 10/25 | G13: 68 | P13: たちすずか | Q13: 直播（乾田） | R13: =SUM(200*$G13+250*$H13+300*$I13) -> 13600 | S13: =R13/D13*1000 -> 2561.6877
A14: Polygon((132.84282267093735.4141749191511,132.84327059984235.414386956862,132.84377485513735.413654659311,132.84330010414135.4135322447429,132.84282267093735.4141749191511)) | B14: （株）錦織農園 | C14: 島根県出雲市斐川町黒目1079 | D14: 4128 | E14: 10/27 | F14: 10/27 | G14: 45 | P14: たちすずか | Q14: 直播（乾田） | R14: =SUM(200*$G14+250*$H14+300*$I14) -> 9000 | S14: =R14/D14*1000 -> 2180.2326
A15: Polygon((132.82727122306835.4142230102273,132.82729536294935.4142864029656,132.82715320587235.4146667583482,132.82697886228635.4151323633552,132.82689303159735.4151607804751,132.82663285732335.4151061321587,132.82643437385635.4154952273638,132.8263673186335.4155083428998,132.82624661922535.415471182209,132.82647997140935.4150580416097,132.82674551010135.4145683907489,132.8267481923135.4145683907489,132.82698422670435.4141268280463,132.82727122306835.4142230102273)) | B15: （株）錦織農園 | C15: 島根県出雲市斐川町三分市8 | D15: 4836 | E15: 10/29 | F15: 10/29 | I15: 47 | P15: たちすずか | Q15: 直播（乾田） | R15: =SUM(200*$G15+250*$H15+300*$I15) -> 14100 | S15: =R15/D15*1000 -> 2915.6328
A16: Polygon((132.82719075679835.4147126631867,132.82711029052735.4149574885507,132.82818585634235.415311609636,132.82831460237535.4150755290854,132.82719075679835.4147126631867)) | B16: （株）錦織農園 | C16: 島根県出雲市斐川町三分市29 | D16: 3074 | E16: 10/29 | F16: 10/29 | I16: 26 | P16: たちすずか | Q16: 直播（乾田） | R16: =SUM(200*$G16+250*$H16+300*$I16) -> 7800 | S16: =R16/D16*1000 -> 2537.4105
A17: Polygon((132.82787740235.412915797,132.82772183435.413287415,132.82737851135.414056877,132.82705128135.413960694,132.82735635235.413186697,132.82734900735.413184673,132.82750725735.412808683,132.82787740235.412915797)) | B17: （株）錦織農園 | C17: 島根県出雲市斐川町三分市110 | D17: 4023 | E17: 10/30 | F17: 10/30 | H17: 22 | P17: たちすずか | Q17: 直播（乾田） | R17: =SUM(200*$G17+250*$H17+300*$I17) -> 5500 | S17: =R17/D17*1000 -> 1367.139
A18: Polygon((132.82830655574835.4130229107037,132.82801151275635.413683076952,132.8282743692435.4137639578755,132.82831728458435.4137377262335,132.82859086990435.4131081642651,132.82830655574835.4130229107037)) | B18: （株）錦織農園 | C18: 島根県出雲市斐川町三分市136 | D18: 1997 | E18: 10/29 | F18: 10/29 | I18: 22 | P18: たちすずか | Q18: 直播（乾田） | R18: =SUM(200*$G18+250*$H18+300*$I18) -> 6600 | S18: =R18/D18*1000 -> 3304.9574
A19: Polygon((132.8410175442735.4146274113229,132.84101217985235.4143935147204,132.84046500921235.4139869264872,132.84037381410635.4142317540562,132.84030675888135.4144656511282,132.8410175442735.4146274113229)) | B19: （株）錦織農園 | C19: 島根県出雲市斐川町三分市864 | D19: 2789 | E19: 10/27 | F19: 10/27 | G19: 27 | P19: たちすずか | Q19: 直播（乾田） | R19: =SUM(200*$G19+250*$H19+300*$I19) -> 5400 | S19: =R19/D19*1000 -> 1936.1778
A20: Polygon((132.84029737114935.4144875106329,132.84020215272935.4147913571348,132.84135282039635.4150449260004,132.84137964248735.4149509307381,132.84102693200135.4146438059191,132.84029737114935.4144875106329)) | B20: （株）錦織農園 | C20: 島根県出雲市斐川町三分市865 | D20: 3470 | E20: 10/27 | F20: 10/27 | G20: 36 | P20: たちすずか | Q20: 直播（乾田） | R20: =SUM(200*$G20+250*$H20+300*$I20) -> 7200 | S20: =R20/D20*1000 -> 2074.928
A21: Polygon((132.84106314182335.4162362517994,132.84100681543435.4164329828056,132.84197509288835.4166428286828,132.8421333432235.4165466493903,132.84210115671235.4164548417767,132.84106314182335.4162362517994)) | B21: （株）錦織農園 | C21: 島根県出雲市斐川町三分市883 | D21: 1967 | E21: 10/28 | F21: 10/28 | G21: 20 | P21: たちすずか | Q21: 直播（乾田） | R21: =SUM(200*$G21+250*$H21+300*$I21) -> 4000 | S21: =R21/D21*1000 -> 2033.5536
A22: Polygon((132.84125089645435.4156263826275,132.84107655286835.4161750464995,132.84173101186835.4163149442595,132.84190803766335.415770653171,132.84125089645435.4156263826275)) | B22: （株）錦織農園 | C22: 島根県出雲市斐川町三分市885 | D22: 3956 | E22: 10/28 | F22: 10/28 | G22: 43 | P22: たちすずか | Q22: 直播（乾田） | R22: =SUM(200*$G22+250*$H22+300*$I22) -> 8600 | S22: =R22/D22*1000 -> 2173.913
A23: Polygon((132.84143865108535.4150908306235,132.8412884473835.4155586191013,132.84179538488435.4156744728374,132.84188389778135.4154318355765,132.84170687198635.4152963081398,132.8417229652435.4152613332804,132.84143865108535.4150908306235)) | B23: （株）錦織農園 | C23: 島根県出雲市斐川町三分市889-1 | D23: 2319 | E23: 10/28 | F23: 10/28 | G23: 23 | P23: たちすずか | Q23: 直播（乾田） | R23: =SUM(200*$G23+250*$H23+300*$I23) -> 4600 | S23: =R23/D23*1000 -> 1983.6136
A24: Polygon((132.86336034536435.4181467081427,132.86304652690935.4190166721071,132.86323159933135.419056016989,132.86330133676535.4190079287974,132.86358028650335.4181991685474,132.86336034536435.4181467081427)) | B24: （株）錦織農園 | C24: 島根県出雲市斐川町三分市2549-1 | D24: 2207 | E24: 10/22 | F24: 10/22 | G24: 24 | P24: たちすずか | Q24: 直播（乾田） | R24: =SUM(200*$G24+250*$H24+300*$I24) -> 4800 | S24: =R24/D24*1000 -> 2174.8981
A25: Polygon((132.86206483840935.4197882654511,132.86237329244635.4188898940237,132.86325573921235.4191062909768,132.8631511330635.4193882618921,132.86284267902435.4193226873487,132.86267101764735.4197379918888,132.8629902005235.4198144951232,132.86292850971235.4199937309879,132.86246180534435.4198822550702,132.86245375871735.419884440874,132.86206483840935.4197882654511)) | B25: （株）錦織農園 | C25: 島根県出雲市斐川町三分市2552-1 | D25: 6763 | E25: 10/22 | F25: 10/22 | G25: 74 | P25: たちすずか | Q25: 直播（乾田） | R25: =SUM(200*$G25+250*$H25+300*$I25) -> 14800 | S25: =R25/D25*1000 -> 2188.3779
A26: Polygon((132.8618448972735.4197259699454,132.86196291446735.4197532925415,132.86227941513135.4188702215445,132.8621721267735.4188428986489,132.8618448972735.4197259699454)) | B26: （株）錦織農園 | C26: 島根県出雲市斐川町三分市2556 | D26: 910 | E26: 10/22 | F26: 10/22 | G26: 22 | P26: たちすずか | Q26: 直播（乾田） | R26: =SUM(200*$G26+250*$H26+300*$I26) -> 4400 | S26: =R26/D26*1000 -> 4835.1648
A27: Polygon((132.86153376102435.4186997265244,132.86121726036135.4195827993901,132.86134332418435.4196090291292,132.86165177822135.4187281423862,132.86153376102435.4186997265244)) | B27: （株）錦織農園 | C27: 島根県出雲市斐川町三分市2560 | D27: 1206 | E27: 10/22 | F27: 10/22 | G27: 11 | P27: たちすずか | Q27: 直播（乾田） | R27: =SUM(200*$G27+250*$H27+300*$I27) -> 2200 | S27: =R27/D27*1000 -> 1824.2123
A28: Polygon((132.86086052656235.4185204877809,132.86129504442235.4186275939073,132.8614908456835.4186778681624,132.86115288734435.4195696845174,132.86094903945935.4195194108188,132.86054939031635.4194276065925,132.86030530929635.4193685895347,132.86015242338235.4193292448054,132.86046892404635.4184286824163,132.86063253879535.4184680275854,132.86086052656235.4185204877809)) | B28: （株）錦織農園 | C28: 島根県出雲市斐川町三分市2563 | D28: 7838 | E28: 10/22 | F28: 10/22 | G28: 90 | P28: たちすずか | Q28: 直播（乾田） | R28: =SUM(200*$G28+250*$H28+300*$I28) -> 18000 | S28: =R28/D28*1000 -> 2296.5042
A29: Polygon((132.861437201535.4204134036478,132.86186635494235.4204920920282,132.86208629608235.4205183214712,132.86201655864735.4206669548204,132.86185026168835.4206538401242,132.86182880401635.4209292482972,132.86095440387735.4208549318988,132.86099731922135.4205838950414,132.86101341247635.4203828025903,132.861437201535.4204134036478)) | B29: （株）錦織農園 | C29: 島根県出雲市斐川町三分市2744-2-1 | D29: 4244 | E29: 10/21 | F29: 10/21 | G29: 51 | P29: たちすずか | Q29: 直播（乾田） | R29: =SUM(200*$G29+250*$H29+300*$I29) -> 10200 | S29: =R29/D29*1000 -> 2403.393
A30: Polygon((132.8610295057335.4203696878478,132.86142110824635.4204046604897,132.86150157451635.420142365305,132.86167860031135.4201511084916,132.86180198192635.4198057519001,132.86122262477935.4196614885818,132.86109387874635.4199369001472,132.8610295057335.4203696878478)) | B30: （株）錦織農園 | C30: 島根県出雲市斐川町三分市2747-2-1 | D30: 2890 | E30: 10/21 | F30: 10/21 | G30: 42 | P30: たちすずか | Q30: 直播（乾田） | R30: =SUM(200*$G30+250*$H30+300*$I30) -> 8400 | S30: =R30/D30*1000 -> 2906.5744
A31: Polygon((132.86187708377835.4204789773034,132.86209702491835.4205095783245,132.86237597465535.4199412717517,132.86202192306535.419866954442,132.86193609237735.4202035675912,132.86198437213935.4202472834814,132.86187708377835.4204789773034)) | B31: （株）錦織農園 | C31: 島根県出雲市斐川町三分市2750-2-1（1） | D31: 1800 | E31: 10/22 | F31: 10/22 | G31: 23 | P31: たちすずか | Q31: 直播（乾田） | R31: =SUM(200*$G31+250*$H31+300*$I31) -> 4600 | S31: =R31/D31*1000 -> 2555.5556
A32: Polygon((132.87364125251835.4214778760581,132.87384778261235.4204265183832,132.87369221448935.4204112178584,132.87361979484635.4207762438729,132.87347763776835.4207587576344,132.87334084510835.4214341608356,132.87364125251835.4214778760581)) | B32: （株）錦織農園 | C32: 島根県出雲市斐川町三分市3591 | D32: 2938 | E32: 8/20 | F32: 8/21 | I32: 33 | J32: 板井牧場 | K32: 8/23 | L32: 運搬 | N32: 錦織農園 | P32: つきはやか | Q32: 直播（乾田） | R32: =SUM(200*$G32+250*$H32+300*$I32) -> 9900 | S32: =R32/D32*1000 -> 3369.6392
A33: Polygon((132.87364125251835.4214756902975,132.87381827831335.4214997336604,132.8740167617835.420435261539,132.8738531470335.4204112178584,132.87364125251835.4214756902975)) | B33: （株）錦織農園 | C33: 島根県出雲市斐川町三分市3592 | D33: 1729 | E33: 8/20 | F33: 8/21 | I33: 20 | J33: 板井牧場 | K33: 8/23 | L33: 運搬 | N33: 錦織農園 | P33: つきはやか | Q33: 直播（乾田） | R33: =SUM(200*$G33+250*$H33+300*$I33) -> 6000 | S33: =R33/D33*1000 -> 3470.214
A34: Polygon((132.87437617778835.4215784209797,132.87459075450935.420513949898,132.87402480840735.420435261539,132.87382364273135.4215019194203,132.87437617778835.4215784209797)) | B34: （株）錦織農園 | C34: 島根県出雲市斐川町三分市3593 | D34: 6252 | E34: 8/20 | F34: 8/21 | I34: 69 | J34: 板井牧場 | K34: 8/23 | L34: 運搬 | N34: 錦織農園 | P34: つきはやか | Q34: 直播（乾田） | R34: =SUM(200*$G34+250*$H34+300*$I34) -> 20700 | S34: =R34/D34*1000 -> 3310.9405
A35: Polygon((132.87438422441535.4215740494639,132.87458270788235.421604650069,132.87463098764435.4215653064318,132.8748321533235.4205970097491,132.87481069564835.4205489224773,132.87460416555435.4205183214712,132.87438422441535.4215740494639)) | B35: （株）錦織農園 | C35: 島根県出雲市斐川町三分市3595 | D35: 2653 | E35: 8/20 | F35: 8/21 | I35: 28 | J35: 板井牧場 | K35: 8/23 | L35: 運搬 | N35: 錦織農園 | P35: つきはやか | Q35: 直播（乾田） | R35: =SUM(200*$G35+250*$H35+300*$I35) -> 8400 | S35: =R35/D35*1000 -> 3166.2269
A36: Polygon((132.87485092878335.4226100920556,132.87503331899635.421709566341,132.87467658519735.4216724085103,132.87449687719335.4225576345231,132.87452906370235.4225773061018,132.87485092878335.4226100920556)) | B36: （株）錦織農園 | C36: 島根県出雲市斐川町三分市3631 | D36: 3356 | E36: 8/21 | F36: 8/21 | I36: 28 | J36: 板井牧場 | K36: 8/23（18本） | L36: 運搬 | M36: 8/26原牧場（残り10本） | N36: 錦織農園 | P36: つきはやか | Q36: 直播（乾田） | R36: =SUM(200*$G36+250*$H36+300*$I36) -> 8400 | S36: =R36/D36*1000 -> 2502.9797
A37: Polygon((132.87525057792735.4226559923685,132.87543028593135.4217707674365,132.87504673004235.4217161236034,132.87486970424735.4226122777854,132.87525057792735.4226559923685)) | B37: （株）錦織農園 | C37: 島根県出雲市斐川町三分市3632 | D37: 2181 | E37: 8/21 | F37: 8/21 | I37: 19 | J37: 原牧場 | K37: 8/26 | L37: 運搬 | N37: 錦織農園 | P37: つきはやか | Q37: 直播（乾田） | R37: =SUM(200*$G37+250*$H37+300*$I37) -> 5700 | S37: =R37/D37*1000 -> 2613.4801
A38: Polygon((132.87525862455435.4226538066399,132.87558853626335.4226865925626,132.87576287984835.4218122967249,132.87542760372235.4217751389416,132.87525862455435.4226538066399)) | B38: （株）錦織農園 | C38: 島根県出雲市斐川町三分市3635 | D38: 4025 | E38: 8/21 | F38: 8/21 | I38: 35 | J38: 原牧場 | K38: 8/26 | L38: 運搬 | N38: 錦織農園 | P38: つきはやか | Q38: 直播（乾田） | R38: =SUM(200*$G38+250*$H38+300*$I38) -> 10500 | S38: =R38/D38*1000 -> 2608.6957
A39: Polygon((132.8765487670935.4227783930751,132.87672311067635.4219325129652,132.87577092647635.4218122967249,132.87560194730835.4226844068348,132.8765487670935.4227783930751)) | B39: （株）錦織農園 | C39: 島根県出雲市斐川町三分市3638-1 | D39: 8045 | E39: 8/20 | F39: 8/21 | I39: 78 | J39: 原牧場 | K39: 8/26 | L39: 運搬 | N39: 錦織農園 | P39: つきはやか | Q39: 直播（乾田） | R39: =SUM(200*$G39+250*$H39+300*$I39) -> 23400 | S39: =R39/D39*1000 -> 2908.6389
A40: Polygon((132.88115143775935.421641807931,132.88119435310435.4214538326887,132.881639599835.4215106624593,132.88143575191535.4225029912238,132.88077592849735.4224243048076,132.88094758987435.4216199503672,132.88115143775935.421641807931)) | B40: （株）錦織農園 | C40: 島根県出雲市斐川町三分市3718 | D40: 6003 | E40: 7/31 | F40: 7/31 | G40: 82 | J40: 日登牧場 | K40: 8/6 | L40: 運搬 | N40: 錦織農園 | P40: ヒメノモチ | Q40: 直播（乾田） | R40: =SUM(200*$G40+250*$H40+300*$I40) -> 16400 | S40: =R40/D40*1000 -> 2731.9673
...

Sheet 集計
A2: 連番 | B2: 経営体名 | C2: 栽培品種 | D2: 栽培面積a | E2: 栽培方法 | F2: 収量kg | G2: 単収kg | J2: 栽培品種 | K2: 栽培方法 | L2: 単収kg
A3: 1 | B3: 原進 | C3: ヒメノモチ | D3: {=SUMPRODUCT((集計!$B3=データ!$B$2:$B$210)*(集計!$C3=データ!$P$2:$P$210)*(集計!$E3=データ!$Q$2:$Q$210)*データ!$D$2:$D$210)/100} -> 90.07 | E3: 移植 | F3: {=SUMPRODUCT((集計!$B3=データ!$B$2:$B$210)*(集計!$C3=データ!$P$2:$P$210)*(集計!$E3=データ!$Q$2:$Q$210)*データ!$R$2:$R$210)} -> 11600 | G3: =F3/D3*10 -> 1287.8872 | J3: たちすずか | K3: 移植 | L3: {=SUMPRODUCT(($J3=$C$3:$C$20)*($K3=$E$3:$E$20)*$F$3:$F$20)/SUMPRODUCT(($J3=$C$3:$C$20)*($K3=$E$3:$E$20)*$D$3:$D$20)*10} -> 2653.5081
A4: 2 | B4: （農）土手町上ファーム | C4: ヒメノモチ | D4: {=SUMPRODUCT((集計!$B4=データ!$B$2:$B$210)*(集計!$C4=データ!$P$2:$P$210)*(集計!$E4=データ!$Q$2:$Q$210)*データ!$D$2:$D$210)/100} -> 349.76 | E4: 移植 | F4: {=SUMPRODUCT((集計!$B4=データ!$B$2:$B$210)*(集計!$C4=データ!$P$2:$P$210)*(集計!$E4=データ!$Q$2:$Q$210)*データ!$R$2:$R$210)} -> 68800 | G4: =F4/D4*10 -> 1967.0631 | J4: たちすずか | K4: 直播（乾田） | L4: {=SUMPRODUCT(($J4=$C$3:$C$20)*($K4=$E$3:$E$20)*$F$3:$F$20)/SUMPRODUCT(($J4=$C$3:$C$20)*($K4=$E$3:$E$20)*$D$3:$D$20)*10} -> 1851.6783
A5: 3 | B5: （有）グリーンサポート斐川 | C5: ヒメノモチ | D5: {=SUMPRODUCT((集計!$B5=データ!$B$2:$B$210)*(集計!$C5=データ!$P$2:$P$210)*(集計!$E5=データ!$Q$2:$Q$210)*データ!$D$2:$D$210)/100} -> 378.55 | E5: 移植 | F5: {=SUMPRODUCT((集計!$B5=データ!$B$2:$B$210)*(集計!$C5=データ!$P$2:$P$210)*(集計!$E5=データ!$Q$2:$Q$210)*データ!$R$2:$R$210)} -> 75000 | G5: =F5/D5*10 -> 1981.2442 | J5: たちすずか | K5: 直播（湛水） | L5: {=SUMPRODUCT(($J5=$C$3:$C$20)*($K5=$E$3:$E$20)*$F$3:$F$20)/SUMPRODUCT(($J5=$C$3:$C$20)*($K5=$E$3:$E$20)*$D$3:$D$20)*10} -> 809.51169
A6: 4 | B6: （株）錦織農園 | C6: ヒメノモチ | D6: {=SUMPRODUCT((集計!$B6=データ!$B$2:$B$210)*(集計!$C6=データ!$P$2:$P$210)*(集計!$E6=データ!$Q$2:$Q$210)*データ!$D$2:$D$210)/100} -> 360.28 | E6: 直播（乾田） | F6: {=SUMPRODUCT((集計!$B6=データ!$B$2:$B$210)*(集計!$C6=データ!$P$2:$P$210)*(集計!$E6=データ!$Q$2:$Q$210)*データ!$R$2:$R$210)} -> 86800 | G6: =F6/D6*10 -> 2409.2373 | J6: つきはやか | K6: 移植 | L6: {=SUMPRODUCT(($J6=$C$3:$C$20)*($K6=$E$3:$E$20)*$F$3:$F$20)/SUMPRODUCT(($J6=$C$3:$C$20)*($K6=$E$3:$E$20)*$D$3:$D$20)*10} -> 3167.7019
A7: 5 | B7: （株）米らいふ | C7: つきはやか | D7: {=SUMPRODUCT((集計!$B7=データ!$B$2:$B$210)*(集計!$C7=データ!$P$2:$P$210)*(集計!$E7=データ!$Q$2:$Q$210)*データ!$D$2:$D$210)/100} -> 385.1 | E7: 移植 | F7: {=SUMPRODUCT((集計!$B7=データ!$B$2:$B$210)*(集計!$C7=データ!$P$2:$P$210)*(集計!$E7=データ!$Q$2:$Q$210)*データ!$R$2:$R$210)} -> 123300 | G7: =F7/D7*10 -> 3201.7658 | J7: つきはやか | K7: 直播（乾田） | L7: {=SUMPRODUCT(($J7=$C$3:$C$20)*($K7=$E$3:$E$20)*$F$3:$F$20)/SUMPRODUCT(($J7=$C$3:$C$20)*($K7=$E$3:$E$20)*$D$3:$D$20)*10} -> 2893.9634
A8: 6 | B8: （農）別名ファーム | C8: きぬむすめ | D8: {=SUMPRODUCT((集計!$B8=データ!$B$2:$B$210)*(集計!$C8=データ!$P$2:$P$210)*(集計!$E8=データ!$Q$2:$Q$210)*データ!$D$2:$D$210)/100} -> 355.05 | E8: 移植 | F8: {=SUMPRODUCT((集計!$B8=データ!$B$2:$B$210)*(集計!$C8=データ!$P$2:$P$210)*(集計!$E8=データ!$Q$2:$Q$210)*データ!$R$2:$R$210)} -> 108800 | G8: =F8/D8*10 -> 3064.3571 | J8: ヒメノモチ | K8: 移植 | L8: {=SUMPRODUCT(($J8=$C$3:$C$20)*($K8=$E$3:$E$20)*$F$3:$F$20)/SUMPRODUCT(($J8=$C$3:$C$20)*($K8=$E$3:$E$20)*$D$3:$D$20)*10} -> 1898.8734
A9: 7 | B9: （農）あっとふぁーむ黒目 | C9: つきはやか | D9: {=SUMPRODUCT((集計!$B9=データ!$B$2:$B$210)*(集計!$C9=データ!$P$2:$P$210)*(集計!$E9=データ!$Q$2:$Q$210)*データ!$D$2:$D$210)/100} -> 194.5 | E9: 移植 | F9: {=SUMPRODUCT((集計!$B9=データ!$B$2:$B$210)*(集計!$C9=データ!$P$2:$P$210)*(集計!$E9=データ!$Q$2:$Q$210)*データ!$R$2:$R$210)} -> 60300 | G9: =F9/D9*10 -> 3100.2571 | J9: ヒメノモチ | K9: 直播（乾田） | L9: {=SUMPRODUCT(($J9=$C$3:$C$20)*($K9=$E$3:$E$20)*$F$3:$F$20)/SUMPRODUCT(($J9=$C$3:$C$20)*($K9=$E$3:$E$20)*$D$3:$D$20)*10} -> 2409.2373
A10: 8 | B10: （有）グリーンサポート斐川 | C10: きぬむすめ | D10: {=SUMPRODUCT((集計!$B10=データ!$B$2:$B$210)*(集計!$C10=データ!$P$2:$P$210)*(集計!$E10=データ!$Q$2:$Q$210)*データ!$D$2:$D$210)/100} -> 384.09 | E10: 移植 | F10: {=SUMPRODUCT((集計!$B10=データ!$B$2:$B$210)*(集計!$C10=データ!$P$2:$P$210)*(集計!$E10=データ!$Q$2:$Q$210)*データ!$R$2:$R$210)} -> 86000 | G10: =F10/D10*10 -> 2239.0586
A11: 9 | B11: （農）土手町上ファーム | C11: きぬむすめ | D11: {=SUMPRODUCT((集計!$B11=データ!$B$2:$B$210)*(集計!$C11=データ!$P$2:$P$210)*(集計!$E11=データ!$Q$2:$Q$210)*データ!$D$2:$D$210)/100} -> 344.63 | E11: 移植 | F11: {=SUMPRODUCT((集計!$B11=データ!$B$2:$B$210)*(集計!$C11=データ!$P$2:$P$210)*(集計!$E11=データ!$Q$2:$Q$210)*データ!$R$2:$R$210)} -> 91500 | G11: =F11/D11*10 -> 2655.0213
A12: 10 | B12: （株）錦織農園 | C12: つきはやか | D12: {=SUMPRODUCT((集計!$B12=データ!$B$2:$B$210)*(集計!$C12=データ!$P$2:$P$210)*(集計!$E12=データ!$Q$2:$Q$210)*データ!$D$2:$D$210)/100} -> 353.84 | E12: 直播（乾田） | F12: {=SUMPRODUCT((集計!$B12=データ!$B$2:$B$210)*(集計!$C12=データ!$P$2:$P$210)*(集計!$E12=データ!$Q$2:$Q$210)*データ!$R$2:$R$210)} -> 102400 | G12: =F12/D12*10 -> 2893.9634
A13: 11 | B13: （株）あかつきファーム今在家 | C13: きぬむすめ | D13: {=SUMPRODUCT((集計!$B13=データ!$B$2:$B$210)*(集計!$C13=データ!$P$2:$P$210)*(集計!$E13=データ!$Q$2:$Q$210)*データ!$D$2:$D$210)/100} -> 1407.97 | E13: 直播（乾田） | F13: {=SUMPRODUCT((集計!$B13=データ!$B$2:$B$210)*(集計!$C13=データ!$P$2:$P$210)*(集計!$E13=データ!$Q$2:$Q$210)*データ!$R$2:$R$210)} -> 241400 | G13: =F13/D13*10 -> 1714.5252
A14: 12 | B14: （農）相場ファーム | C14: たちすずか | D14: {=SUMPRODUCT((集計!$B14=データ!$B$2:$B$210)*(集計!$C14=データ!$P$2:$P$210)*(集計!$E14=データ!$Q$2:$Q$210)*データ!$D$2:$D$210)/100} -> 768.17 | E14: 直播（乾田） | F14: {=SUMPRODUCT((集計!$B14=データ!$B$2:$B$210)*(集計!$C14=データ!$P$2:$P$210)*(集計!$E14=データ!$Q$2:$Q$210)*データ!$R$2:$R$210)} -> 133000 | G14: =F14/D14*10 -> 1731.3876
A15: 13 | B15: （株）錦織農園 | C15: たちすずか | D15: {=SUMPRODUCT((集計!$B15=データ!$B$2:$B$210)*(集計!$C15=データ!$P$2:$P$210)*(集計!$E15=データ!$Q$2:$Q$210)*データ!$D$2:$D$210)/100} -> 1251.92 | E15: 直播（乾田） | F15: {=SUMPRODUCT((集計!$B15=データ!$B$2:$B$210)*(集計!$C15=データ!$P$2:$P$210)*(集計!$E15=データ!$Q$2:$Q$210)*データ!$R$2:$R$210)} -> 310700 | G15: =F15/D15*10 -> 2481.788
A16: 14 | B16: どてまち営農組合 | C16: たちすずか | D16: {=SUMPRODUCT((集計!$B16=データ!$B$2:$B$210)*(集計!$C16=データ!$P$2:$P$210)*(集計!$E16=データ!$Q$2:$Q$210)*データ!$D$2:$D$210)/100} -> 408.35 | E16: 移植 | F16: {=SUMPRODUCT((集計!$B16=データ!$B$2:$B$210)*(集計!$C16=データ!$P$2:$P$210)*(集計!$E16=データ!$Q$2:$Q$210)*データ!$R$2:$R$210)} -> 90900 | G16: =F16/D16*10 -> 2226.0316
A17: 15 | B17: （農）じきょう | C17: たちすずか | D17: {=SUMPRODUCT((集計!$B17=データ!$B$2:$B$210)*(集計!$C17=データ!$P$2:$P$210)*(集計!$E17=データ!$Q$2:$Q$210)*データ!$D$2:$D$210)/100} -> 966.93 | E17: 直播（乾田） | F17: {=SUMPRODUCT((集計!$B17=データ!$B$2:$B$210)*(集計!$C17=データ!$P$2:$P$210)*(集計!$E17=データ!$Q$2:$Q$210)*データ!$R$2:$R$210)} -> 109400 | G17: =F17/D17*10 -> 1131.4159
A18: 16 | B18: （株）米らいふ | C18: たちすずか | D18: {=SUMPRODUCT((集計!$B18=データ!$B$2:$B$210)*(集計!$C18=データ!$P$2:$P$210)*(集計!$E18=データ!$Q$2:$Q$210)*データ!$D$2:$D$210)/100} -> 215.56 | E18: 移植 | F18: {=SUMPRODUCT((集計!$B18=データ!$B$2:$B$210)*(集計!$C18=データ!$P$2:$P$210)*(集計!$E18=データ!$Q$2:$Q$210)*データ!$R$2:$R$210)} -> 86100 | G18: =F18/D18*10 -> 3994.2475
A19: 17 | B19: （農）おきす | C19: たちすずか | D19: {=SUMPRODUCT((集計!$B19=データ!$B$2:$B$210)*(集計!$C19=データ!$P$2:$P$210)*(集計!$E19=データ!$Q$2:$Q$210)*データ!$D$2:$D$210)/100} -> 1689.29 | E19: 直播（湛水） | F19: {=SUMPRODUCT((集計!$B19=データ!$B$2:$B$210)*(集計!$C19=データ!$P$2:$P$210)*(集計!$E19=データ!$Q$2:$Q$210)*データ!$R$2:$R$210)} -> 136750 | G19: =F19/D19*10 -> 809.51169
A20: 18 | B20: （農）碇下ファーム | C20: たちすずか | D20: {=SUMPRODUCT((集計!$B20=データ!$B$2:$B$210)*(集計!$C20=データ!$P$2:$P$210)*(集計!$E20=データ!$Q$2:$Q$210)*データ!$D$2:$D$210)/100} -> 385.32 | E20: 移植 | F20: {=SUMPRODUCT((集計!$B20=データ!$B$2:$B$210)*(集計!$C20=データ!$P$2:$P$210)*(集計!$E20=データ!$Q$2:$Q$210)*データ!$R$2:$R$210)} -> 90800 | G20: =F20/D20*10 -> 2356.4829
